*** Starting uWSGI 1.9.18.2 (64bit) on [Wed Nov  6 11:46:09 2013] ***
compiled with version: 4.6.3 on 30 October 2013 14:32:07
os: Linux-3.8.0-29-generic #42~precise1-Ubuntu SMP Wed Aug 14 16:19:23 UTC 2013
nodename: emhagman
machine: x86_64
clock source: unix
detected number of CPU cores: 1
current working directory: /root/bartalk-server
detected binary path: /usr/local/bin/uwsgi
!!! no internal routing support, rebuild with pcre support !!!
uWSGI running as root, you can use --uid/--gid/--chroot options
*** WARNING: you are running uWSGI as root !!! (use the --uid flag) *** 
*** WARNING: you are running uWSGI without its master process manager ***
your processes number limit is 3781
your memory page size is 4096 bytes
detected max file descriptor number: 1024
lock engine: pthread robust mutexes
thunder lock: disabled (you can enable it with --thunder-lock)
uwsgi socket 0 bound to TCP address :9003 fd 3
Python version: 2.7.3 (default, Sep 26 2013, 20:13:52)  [GCC 4.6.3]
Python main interpreter initialized at 0xcdd080
python threads support enabled
your server socket listen backlog is limited to 100 connections
your mercy for graceful operations on workers is 60 seconds
mapped 72800 bytes (71 KB) for 1 cores
*** Operational MODE: single process ***
WSGI app 0 (mountpoint='') ready in 0 seconds on interpreter 0xcdd080 pid: 22028 (default app)
*** uWSGI is running in multiple interpreter mode ***
spawned uWSGI worker 1 (and the only) (pid: 22028, cores: 1)
Traceback (most recent call last):
  File "/usr/local/lib/python2.7/dist-packages/django/core/handlers/wsgi.py", line 236, in __call__
    self.load_middleware()
  File "/usr/local/lib/python2.7/dist-packages/django/core/handlers/base.py", line 45, in load_middleware
    for middleware_path in settings.MIDDLEWARE_CLASSES:
  File "/usr/local/lib/python2.7/dist-packages/django/conf/__init__.py", line 53, in __getattr__
    self._setup(name)
  File "/usr/local/lib/python2.7/dist-packages/django/conf/__init__.py", line 48, in _setup
    self._wrapped = Settings(settings_module)
  File "/usr/local/lib/python2.7/dist-packages/django/conf/__init__.py", line 132, in __init__
    mod = importlib.import_module(self.SETTINGS_MODULE)
  File "/usr/local/lib/python2.7/dist-packages/django/utils/importlib.py", line 35, in import_module
    __import__(name)
  File "./bartalk/settings.py", line 4, in <module>
    Database.connect()
  File "./tools/database.py", line 61, in connect
    Database.connection = Database.engine.connect()
  File "/usr/local/lib/python2.7/dist-packages/sqlalchemy/engine/base.py", line 1641, in connect
    return self._connection_cls(self, **kwargs)
  File "/usr/local/lib/python2.7/dist-packages/sqlalchemy/engine/base.py", line 59, in __init__
    self.__connection = connection or engine.raw_connection()
  File "/usr/local/lib/python2.7/dist-packages/sqlalchemy/engine/base.py", line 1699, in raw_connection
    return self.pool.unique_connection()
  File "/usr/local/lib/python2.7/dist-packages/sqlalchemy/pool.py", line 220, in unique_connection
    return _ConnectionFairy(self).checkout()
  File "/usr/local/lib/python2.7/dist-packages/sqlalchemy/pool.py", line 431, in __init__
    rec = self._connection_record = pool._do_get()
  File "/usr/local/lib/python2.7/dist-packages/sqlalchemy/pool.py", line 788, in _do_get
    con = self._create_connection()
  File "/usr/local/lib/python2.7/dist-packages/sqlalchemy/pool.py", line 225, in _create_connection
    return _ConnectionRecord(self)
  File "/usr/local/lib/python2.7/dist-packages/sqlalchemy/pool.py", line 318, in __init__
    self.connection = self.__connect()
  File "/usr/local/lib/python2.7/dist-packages/sqlalchemy/pool.py", line 379, in __connect
    connection = self.__pool._creator()
  File "/usr/local/lib/python2.7/dist-packages/sqlalchemy/engine/strategies.py", line 80, in connect
    return dialect.connect(*cargs, **cparams)
  File "/usr/local/lib/python2.7/dist-packages/sqlalchemy/engine/default.py", line 283, in connect
    return self.dbapi.connect(*cargs, **cparams)
  File "/usr/local/lib/python2.7/dist-packages/psycopg2/__init__.py", line 164, in connect
    conn = _connect(dsn, connection_factory=connection_factory, async=async)
sqlalchemy.exc.OperationalError: (OperationalError) fe_sendauth: no password supplied
 None None
[pid: 22028|app: 0|req: 1/1] 153.104.158.128 () {40 vars in 715 bytes} [Wed Nov  6 11:46:12 2013] GET /api/bars/list => generated 0 bytes in 251 msecs (HTTP/1.1 500) 0 headers in 0 bytes (0 switches on core 0)
Traceback (most recent call last):
  File "/usr/local/lib/python2.7/dist-packages/django/core/handlers/wsgi.py", line 236, in __call__
    self.load_middleware()
  File "/usr/local/lib/python2.7/dist-packages/django/core/handlers/base.py", line 45, in load_middleware
    for middleware_path in settings.MIDDLEWARE_CLASSES:
  File "/usr/local/lib/python2.7/dist-packages/django/conf/__init__.py", line 53, in __getattr__
    self._setup(name)
  File "/usr/local/lib/python2.7/dist-packages/django/conf/__init__.py", line 48, in _setup
    self._wrapped = Settings(settings_module)
  File "/usr/local/lib/python2.7/dist-packages/django/conf/__init__.py", line 132, in __init__
    mod = importlib.import_module(self.SETTINGS_MODULE)
  File "/usr/local/lib/python2.7/dist-packages/django/utils/importlib.py", line 35, in import_module
    __import__(name)
  File "./bartalk/settings.py", line 4, in <module>
    Database.connect()
  File "./tools/database.py", line 61, in connect
    Database.connection = Database.engine.connect()
  File "/usr/local/lib/python2.7/dist-packages/sqlalchemy/engine/base.py", line 1641, in connect
    return self._connection_cls(self, **kwargs)
  File "/usr/local/lib/python2.7/dist-packages/sqlalchemy/engine/base.py", line 59, in __init__
    self.__connection = connection or engine.raw_connection()
  File "/usr/local/lib/python2.7/dist-packages/sqlalchemy/engine/base.py", line 1699, in raw_connection
    return self.pool.unique_connection()
  File "/usr/local/lib/python2.7/dist-packages/sqlalchemy/pool.py", line 220, in unique_connection
    return _ConnectionFairy(self).checkout()
  File "/usr/local/lib/python2.7/dist-packages/sqlalchemy/pool.py", line 431, in __init__
    rec = self._connection_record = pool._do_get()
  File "/usr/local/lib/python2.7/dist-packages/sqlalchemy/pool.py", line 788, in _do_get
    con = self._create_connection()
  File "/usr/local/lib/python2.7/dist-packages/sqlalchemy/pool.py", line 225, in _create_connection
    return _ConnectionRecord(self)
  File "/usr/local/lib/python2.7/dist-packages/sqlalchemy/pool.py", line 318, in __init__
    self.connection = self.__connect()
  File "/usr/local/lib/python2.7/dist-packages/sqlalchemy/pool.py", line 379, in __connect
    connection = self.__pool._creator()
  File "/usr/local/lib/python2.7/dist-packages/sqlalchemy/engine/strategies.py", line 80, in connect
    return dialect.connect(*cargs, **cparams)
  File "/usr/local/lib/python2.7/dist-packages/sqlalchemy/engine/default.py", line 283, in connect
    return self.dbapi.connect(*cargs, **cparams)
  File "/usr/local/lib/python2.7/dist-packages/psycopg2/__init__.py", line 164, in connect
    conn = _connect(dsn, connection_factory=connection_factory, async=async)
sqlalchemy.exc.OperationalError: (OperationalError) fe_sendauth: no password supplied
 None None
[pid: 22028|app: 0|req: 2/2] 153.104.158.128 () {40 vars in 715 bytes} [Wed Nov  6 11:46:25 2013] GET /api/bars/list => generated 0 bytes in 19 msecs (HTTP/1.1 500) 0 headers in 0 bytes (0 switches on core 0)
*** Starting uWSGI 1.9.18.2 (64bit) on [Wed Nov  6 11:48:29 2013] ***
compiled with version: 4.6.3 on 30 October 2013 14:32:07
os: Linux-3.8.0-29-generic #42~precise1-Ubuntu SMP Wed Aug 14 16:19:23 UTC 2013
nodename: emhagman
machine: x86_64
clock source: unix
detected number of CPU cores: 1
current working directory: /root/bartalk-server
detected binary path: /usr/local/bin/uwsgi
!!! no internal routing support, rebuild with pcre support !!!
uWSGI running as root, you can use --uid/--gid/--chroot options
*** WARNING: you are running uWSGI as root !!! (use the --uid flag) *** 
your processes number limit is 3781
your memory page size is 4096 bytes
detected max file descriptor number: 1024
lock engine: pthread robust mutexes
thunder lock: disabled (you can enable it with --thunder-lock)
uwsgi socket 0 bound to TCP address :9003 fd 3
Python version: 2.7.3 (default, Sep 26 2013, 20:13:52)  [GCC 4.6.3]
Python main interpreter initialized at 0x213b0e0
python threads support enabled
your server socket listen backlog is limited to 100 connections
your mercy for graceful operations on workers is 60 seconds
mapped 145600 bytes (142 KB) for 1 cores
*** Operational MODE: single process ***
WSGI app 0 (mountpoint='') ready in 0 seconds on interpreter 0x213b0e0 pid: 22169 (default app)
*** uWSGI is running in multiple interpreter mode ***
spawned uWSGI master process (pid: 22169)
spawned uWSGI worker 1 (pid: 22170, cores: 1)
Python auto-reloader enabled
Traceback (most recent call last):
  File "/usr/local/lib/python2.7/dist-packages/django/core/handlers/wsgi.py", line 236, in __call__
    self.load_middleware()
  File "/usr/local/lib/python2.7/dist-packages/django/core/handlers/base.py", line 45, in load_middleware
    for middleware_path in settings.MIDDLEWARE_CLASSES:
  File "/usr/local/lib/python2.7/dist-packages/django/conf/__init__.py", line 53, in __getattr__
    self._setup(name)
  File "/usr/local/lib/python2.7/dist-packages/django/conf/__init__.py", line 48, in _setup
    self._wrapped = Settings(settings_module)
  File "/usr/local/lib/python2.7/dist-packages/django/conf/__init__.py", line 132, in __init__
    mod = importlib.import_module(self.SETTINGS_MODULE)
  File "/usr/local/lib/python2.7/dist-packages/django/utils/importlib.py", line 35, in import_module
    __import__(name)
  File "./bartalk/settings.py", line 4, in <module>
    Database.connect()
  File "./tools/database.py", line 61, in connect
    Database.connection = Database.engine.connect()
  File "/usr/local/lib/python2.7/dist-packages/sqlalchemy/engine/base.py", line 1641, in connect
    return self._connection_cls(self, **kwargs)
  File "/usr/local/lib/python2.7/dist-packages/sqlalchemy/engine/base.py", line 59, in __init__
    self.__connection = connection or engine.raw_connection()
  File "/usr/local/lib/python2.7/dist-packages/sqlalchemy/engine/base.py", line 1699, in raw_connection
    return self.pool.unique_connection()
  File "/usr/local/lib/python2.7/dist-packages/sqlalchemy/pool.py", line 220, in unique_connection
    return _ConnectionFairy(self).checkout()
  File "/usr/local/lib/python2.7/dist-packages/sqlalchemy/pool.py", line 431, in __init__
    rec = self._connection_record = pool._do_get()
  File "/usr/local/lib/python2.7/dist-packages/sqlalchemy/pool.py", line 788, in _do_get
    con = self._create_connection()
  File "/usr/local/lib/python2.7/dist-packages/sqlalchemy/pool.py", line 225, in _create_connection
    return _ConnectionRecord(self)
  File "/usr/local/lib/python2.7/dist-packages/sqlalchemy/pool.py", line 318, in __init__
    self.connection = self.__connect()
  File "/usr/local/lib/python2.7/dist-packages/sqlalchemy/pool.py", line 379, in __connect
    connection = self.__pool._creator()
  File "/usr/local/lib/python2.7/dist-packages/sqlalchemy/engine/strategies.py", line 80, in connect
    return dialect.connect(*cargs, **cparams)
  File "/usr/local/lib/python2.7/dist-packages/sqlalchemy/engine/default.py", line 283, in connect
    return self.dbapi.connect(*cargs, **cparams)
  File "/usr/local/lib/python2.7/dist-packages/psycopg2/__init__.py", line 164, in connect
    conn = _connect(dsn, connection_factory=connection_factory, async=async)
sqlalchemy.exc.OperationalError: (OperationalError) fe_sendauth: no password supplied
 None None
[pid: 22170|app: 0|req: 1/1] 153.104.158.128 () {40 vars in 715 bytes} [Wed Nov  6 11:48:39 2013] GET /api/bars/list => generated 0 bytes in 143 msecs (HTTP/1.1 500) 0 headers in 0 bytes (0 switches on core 0)
Traceback (most recent call last):
  File "/usr/local/lib/python2.7/dist-packages/django/core/handlers/wsgi.py", line 236, in __call__
    self.load_middleware()
  File "/usr/local/lib/python2.7/dist-packages/django/core/handlers/base.py", line 45, in load_middleware
    for middleware_path in settings.MIDDLEWARE_CLASSES:
  File "/usr/local/lib/python2.7/dist-packages/django/conf/__init__.py", line 53, in __getattr__
    self._setup(name)
  File "/usr/local/lib/python2.7/dist-packages/django/conf/__init__.py", line 48, in _setup
    self._wrapped = Settings(settings_module)
  File "/usr/local/lib/python2.7/dist-packages/django/conf/__init__.py", line 132, in __init__
    mod = importlib.import_module(self.SETTINGS_MODULE)
  File "/usr/local/lib/python2.7/dist-packages/django/utils/importlib.py", line 35, in import_module
    __import__(name)
  File "./bartalk/settings.py", line 4, in <module>
    Database.connect()
  File "./tools/database.py", line 61, in connect
    Database.connection = Database.engine.connect()
  File "/usr/local/lib/python2.7/dist-packages/sqlalchemy/engine/base.py", line 1641, in connect
    return self._connection_cls(self, **kwargs)
  File "/usr/local/lib/python2.7/dist-packages/sqlalchemy/engine/base.py", line 59, in __init__
    self.__connection = connection or engine.raw_connection()
  File "/usr/local/lib/python2.7/dist-packages/sqlalchemy/engine/base.py", line 1699, in raw_connection
    return self.pool.unique_connection()
  File "/usr/local/lib/python2.7/dist-packages/sqlalchemy/pool.py", line 220, in unique_connection
    return _ConnectionFairy(self).checkout()
  File "/usr/local/lib/python2.7/dist-packages/sqlalchemy/pool.py", line 431, in __init__
    rec = self._connection_record = pool._do_get()
  File "/usr/local/lib/python2.7/dist-packages/sqlalchemy/pool.py", line 788, in _do_get
    con = self._create_connection()
  File "/usr/local/lib/python2.7/dist-packages/sqlalchemy/pool.py", line 225, in _create_connection
    return _ConnectionRecord(self)
  File "/usr/local/lib/python2.7/dist-packages/sqlalchemy/pool.py", line 318, in __init__
    self.connection = self.__connect()
  File "/usr/local/lib/python2.7/dist-packages/sqlalchemy/pool.py", line 379, in __connect
    connection = self.__pool._creator()
  File "/usr/local/lib/python2.7/dist-packages/sqlalchemy/engine/strategies.py", line 80, in connect
    return dialect.connect(*cargs, **cparams)
  File "/usr/local/lib/python2.7/dist-packages/sqlalchemy/engine/default.py", line 283, in connect
    return self.dbapi.connect(*cargs, **cparams)
  File "/usr/local/lib/python2.7/dist-packages/psycopg2/__init__.py", line 164, in connect
    conn = _connect(dsn, connection_factory=connection_factory, async=async)
sqlalchemy.exc.OperationalError: (OperationalError) fe_sendauth: no password supplied
 None None
[pid: 22170|app: 0|req: 2/2] 153.104.158.128 () {40 vars in 715 bytes} [Wed Nov  6 11:49:30 2013] GET /api/bars/list => generated 0 bytes in 18 msecs (HTTP/1.1 500) 0 headers in 0 bytes (0 switches on core 0)
Traceback (most recent call last):
  File "/usr/local/lib/python2.7/dist-packages/django/core/handlers/wsgi.py", line 236, in __call__
    self.load_middleware()
  File "/usr/local/lib/python2.7/dist-packages/django/core/handlers/base.py", line 45, in load_middleware
    for middleware_path in settings.MIDDLEWARE_CLASSES:
  File "/usr/local/lib/python2.7/dist-packages/django/conf/__init__.py", line 53, in __getattr__
    self._setup(name)
  File "/usr/local/lib/python2.7/dist-packages/django/conf/__init__.py", line 48, in _setup
    self._wrapped = Settings(settings_module)
  File "/usr/local/lib/python2.7/dist-packages/django/conf/__init__.py", line 132, in __init__
    mod = importlib.import_module(self.SETTINGS_MODULE)
  File "/usr/local/lib/python2.7/dist-packages/django/utils/importlib.py", line 35, in import_module
    __import__(name)
  File "./bartalk/settings.py", line 4, in <module>
    Database.connect()
  File "./tools/database.py", line 61, in connect
    Database.connection = Database.engine.connect()
  File "/usr/local/lib/python2.7/dist-packages/sqlalchemy/engine/base.py", line 1641, in connect
    return self._connection_cls(self, **kwargs)
  File "/usr/local/lib/python2.7/dist-packages/sqlalchemy/engine/base.py", line 59, in __init__
    self.__connection = connection or engine.raw_connection()
  File "/usr/local/lib/python2.7/dist-packages/sqlalchemy/engine/base.py", line 1699, in raw_connection
    return self.pool.unique_connection()
  File "/usr/local/lib/python2.7/dist-packages/sqlalchemy/pool.py", line 220, in unique_connection
    return _ConnectionFairy(self).checkout()
  File "/usr/local/lib/python2.7/dist-packages/sqlalchemy/pool.py", line 431, in __init__
    rec = self._connection_record = pool._do_get()
  File "/usr/local/lib/python2.7/dist-packages/sqlalchemy/pool.py", line 788, in _do_get
    con = self._create_connection()
  File "/usr/local/lib/python2.7/dist-packages/sqlalchemy/pool.py", line 225, in _create_connection
    return _ConnectionRecord(self)
  File "/usr/local/lib/python2.7/dist-packages/sqlalchemy/pool.py", line 318, in __init__
    self.connection = self.__connect()
  File "/usr/local/lib/python2.7/dist-packages/sqlalchemy/pool.py", line 379, in __connect
    connection = self.__pool._creator()
  File "/usr/local/lib/python2.7/dist-packages/sqlalchemy/engine/strategies.py", line 80, in connect
    return dialect.connect(*cargs, **cparams)
  File "/usr/local/lib/python2.7/dist-packages/sqlalchemy/engine/default.py", line 283, in connect
    return self.dbapi.connect(*cargs, **cparams)
  File "/usr/local/lib/python2.7/dist-packages/psycopg2/__init__.py", line 164, in connect
    conn = _connect(dsn, connection_factory=connection_factory, async=async)
sqlalchemy.exc.OperationalError: (OperationalError) fe_sendauth: no password supplied
 None None
[pid: 22170|app: 0|req: 3/3] 153.104.158.128 () {40 vars in 715 bytes} [Wed Nov  6 11:52:42 2013] GET /api/bars/list => generated 0 bytes in 16 msecs (HTTP/1.1 500) 0 headers in 0 bytes (0 switches on core 0)
Traceback (most recent call last):
  File "/usr/local/lib/python2.7/dist-packages/django/core/handlers/wsgi.py", line 236, in __call__
    self.load_middleware()
  File "/usr/local/lib/python2.7/dist-packages/django/core/handlers/base.py", line 45, in load_middleware
    for middleware_path in settings.MIDDLEWARE_CLASSES:
  File "/usr/local/lib/python2.7/dist-packages/django/conf/__init__.py", line 53, in __getattr__
    self._setup(name)
  File "/usr/local/lib/python2.7/dist-packages/django/conf/__init__.py", line 48, in _setup
    self._wrapped = Settings(settings_module)
  File "/usr/local/lib/python2.7/dist-packages/django/conf/__init__.py", line 132, in __init__
    mod = importlib.import_module(self.SETTINGS_MODULE)
  File "/usr/local/lib/python2.7/dist-packages/django/utils/importlib.py", line 35, in import_module
    __import__(name)
  File "./bartalk/settings.py", line 4, in <module>
    Database.connect()
  File "./tools/database.py", line 61, in connect
    Database.connection = Database.engine.connect()
  File "/usr/local/lib/python2.7/dist-packages/sqlalchemy/engine/base.py", line 1641, in connect
    return self._connection_cls(self, **kwargs)
  File "/usr/local/lib/python2.7/dist-packages/sqlalchemy/engine/base.py", line 59, in __init__
    self.__connection = connection or engine.raw_connection()
  File "/usr/local/lib/python2.7/dist-packages/sqlalchemy/engine/base.py", line 1699, in raw_connection
    return self.pool.unique_connection()
  File "/usr/local/lib/python2.7/dist-packages/sqlalchemy/pool.py", line 220, in unique_connection
    return _ConnectionFairy(self).checkout()
  File "/usr/local/lib/python2.7/dist-packages/sqlalchemy/pool.py", line 431, in __init__
    rec = self._connection_record = pool._do_get()
  File "/usr/local/lib/python2.7/dist-packages/sqlalchemy/pool.py", line 788, in _do_get
    con = self._create_connection()
  File "/usr/local/lib/python2.7/dist-packages/sqlalchemy/pool.py", line 225, in _create_connection
    return _ConnectionRecord(self)
  File "/usr/local/lib/python2.7/dist-packages/sqlalchemy/pool.py", line 318, in __init__
    self.connection = self.__connect()
  File "/usr/local/lib/python2.7/dist-packages/sqlalchemy/pool.py", line 379, in __connect
    connection = self.__pool._creator()
  File "/usr/local/lib/python2.7/dist-packages/sqlalchemy/engine/strategies.py", line 80, in connect
    return dialect.connect(*cargs, **cparams)
  File "/usr/local/lib/python2.7/dist-packages/sqlalchemy/engine/default.py", line 283, in connect
    return self.dbapi.connect(*cargs, **cparams)
  File "/usr/local/lib/python2.7/dist-packages/psycopg2/__init__.py", line 164, in connect
    conn = _connect(dsn, connection_factory=connection_factory, async=async)
sqlalchemy.exc.OperationalError: (OperationalError) fe_sendauth: no password supplied
 None None
[pid: 22170|app: 0|req: 4/4] 153.104.158.128 () {40 vars in 715 bytes} [Wed Nov  6 11:52:43 2013] GET /api/bars/list => generated 0 bytes in 17 msecs (HTTP/1.1 500) 0 headers in 0 bytes (0 switches on core 0)
Traceback (most recent call last):
  File "/usr/local/lib/python2.7/dist-packages/django/core/handlers/wsgi.py", line 236, in __call__
    self.load_middleware()
  File "/usr/local/lib/python2.7/dist-packages/django/core/handlers/base.py", line 45, in load_middleware
    for middleware_path in settings.MIDDLEWARE_CLASSES:
  File "/usr/local/lib/python2.7/dist-packages/django/conf/__init__.py", line 53, in __getattr__
    self._setup(name)
  File "/usr/local/lib/python2.7/dist-packages/django/conf/__init__.py", line 48, in _setup
    self._wrapped = Settings(settings_module)
  File "/usr/local/lib/python2.7/dist-packages/django/conf/__init__.py", line 132, in __init__
    mod = importlib.import_module(self.SETTINGS_MODULE)
  File "/usr/local/lib/python2.7/dist-packages/django/utils/importlib.py", line 35, in import_module
    __import__(name)
  File "./bartalk/settings.py", line 4, in <module>
    Database.connect()
  File "./tools/database.py", line 61, in connect
    Database.connection = Database.engine.connect()
  File "/usr/local/lib/python2.7/dist-packages/sqlalchemy/engine/base.py", line 1641, in connect
    return self._connection_cls(self, **kwargs)
  File "/usr/local/lib/python2.7/dist-packages/sqlalchemy/engine/base.py", line 59, in __init__
    self.__connection = connection or engine.raw_connection()
  File "/usr/local/lib/python2.7/dist-packages/sqlalchemy/engine/base.py", line 1699, in raw_connection
    return self.pool.unique_connection()
  File "/usr/local/lib/python2.7/dist-packages/sqlalchemy/pool.py", line 220, in unique_connection
    return _ConnectionFairy(self).checkout()
  File "/usr/local/lib/python2.7/dist-packages/sqlalchemy/pool.py", line 431, in __init__
    rec = self._connection_record = pool._do_get()
  File "/usr/local/lib/python2.7/dist-packages/sqlalchemy/pool.py", line 788, in _do_get
    con = self._create_connection()
  File "/usr/local/lib/python2.7/dist-packages/sqlalchemy/pool.py", line 225, in _create_connection
    return _ConnectionRecord(self)
  File "/usr/local/lib/python2.7/dist-packages/sqlalchemy/pool.py", line 318, in __init__
    self.connection = self.__connect()
  File "/usr/local/lib/python2.7/dist-packages/sqlalchemy/pool.py", line 379, in __connect
    connection = self.__pool._creator()
  File "/usr/local/lib/python2.7/dist-packages/sqlalchemy/engine/strategies.py", line 80, in connect
    return dialect.connect(*cargs, **cparams)
  File "/usr/local/lib/python2.7/dist-packages/sqlalchemy/engine/default.py", line 283, in connect
    return self.dbapi.connect(*cargs, **cparams)
  File "/usr/local/lib/python2.7/dist-packages/psycopg2/__init__.py", line 164, in connect
    conn = _connect(dsn, connection_factory=connection_factory, async=async)
sqlalchemy.exc.OperationalError: (OperationalError) fe_sendauth: no password supplied
 None None
[pid: 22170|app: 0|req: 5/5] 153.104.158.128 () {38 vars in 684 bytes} [Wed Nov  6 11:52:56 2013] GET /api/bars/list => generated 0 bytes in 19 msecs (HTTP/1.1 500) 0 headers in 0 bytes (0 switches on core 0)
Traceback (most recent call last):
  File "/usr/local/lib/python2.7/dist-packages/django/core/handlers/wsgi.py", line 236, in __call__
    self.load_middleware()
  File "/usr/local/lib/python2.7/dist-packages/django/core/handlers/base.py", line 45, in load_middleware
    for middleware_path in settings.MIDDLEWARE_CLASSES:
  File "/usr/local/lib/python2.7/dist-packages/django/conf/__init__.py", line 53, in __getattr__
    self._setup(name)
  File "/usr/local/lib/python2.7/dist-packages/django/conf/__init__.py", line 48, in _setup
    self._wrapped = Settings(settings_module)
  File "/usr/local/lib/python2.7/dist-packages/django/conf/__init__.py", line 132, in __init__
    mod = importlib.import_module(self.SETTINGS_MODULE)
  File "/usr/local/lib/python2.7/dist-packages/django/utils/importlib.py", line 35, in import_module
    __import__(name)
  File "./bartalk/settings.py", line 4, in <module>
    Database.connect()
  File "./tools/database.py", line 61, in connect
    Database.connection = Database.engine.connect()
  File "/usr/local/lib/python2.7/dist-packages/sqlalchemy/engine/base.py", line 1641, in connect
    return self._connection_cls(self, **kwargs)
  File "/usr/local/lib/python2.7/dist-packages/sqlalchemy/engine/base.py", line 59, in __init__
    self.__connection = connection or engine.raw_connection()
  File "/usr/local/lib/python2.7/dist-packages/sqlalchemy/engine/base.py", line 1699, in raw_connection
    return self.pool.unique_connection()
  File "/usr/local/lib/python2.7/dist-packages/sqlalchemy/pool.py", line 220, in unique_connection
    return _ConnectionFairy(self).checkout()
  File "/usr/local/lib/python2.7/dist-packages/sqlalchemy/pool.py", line 431, in __init__
    rec = self._connection_record = pool._do_get()
  File "/usr/local/lib/python2.7/dist-packages/sqlalchemy/pool.py", line 788, in _do_get
    con = self._create_connection()
  File "/usr/local/lib/python2.7/dist-packages/sqlalchemy/pool.py", line 225, in _create_connection
    return _ConnectionRecord(self)
  File "/usr/local/lib/python2.7/dist-packages/sqlalchemy/pool.py", line 318, in __init__
    self.connection = self.__connect()
  File "/usr/local/lib/python2.7/dist-packages/sqlalchemy/pool.py", line 379, in __connect
    connection = self.__pool._creator()
  File "/usr/local/lib/python2.7/dist-packages/sqlalchemy/engine/strategies.py", line 80, in connect
    return dialect.connect(*cargs, **cparams)
  File "/usr/local/lib/python2.7/dist-packages/sqlalchemy/engine/default.py", line 283, in connect
    return self.dbapi.connect(*cargs, **cparams)
  File "/usr/local/lib/python2.7/dist-packages/psycopg2/__init__.py", line 164, in connect
    conn = _connect(dsn, connection_factory=connection_factory, async=async)
sqlalchemy.exc.OperationalError: (OperationalError) fe_sendauth: no password supplied
 None None
[pid: 22170|app: 0|req: 6/6] 153.104.158.128 () {38 vars in 666 bytes} [Wed Nov  6 11:52:58 2013] GET /api/ => generated 0 bytes in 15 msecs (HTTP/1.1 500) 0 headers in 0 bytes (0 switches on core 0)
Traceback (most recent call last):
  File "/usr/local/lib/python2.7/dist-packages/django/core/handlers/wsgi.py", line 236, in __call__
    self.load_middleware()
  File "/usr/local/lib/python2.7/dist-packages/django/core/handlers/base.py", line 45, in load_middleware
    for middleware_path in settings.MIDDLEWARE_CLASSES:
  File "/usr/local/lib/python2.7/dist-packages/django/conf/__init__.py", line 53, in __getattr__
    self._setup(name)
  File "/usr/local/lib/python2.7/dist-packages/django/conf/__init__.py", line 48, in _setup
    self._wrapped = Settings(settings_module)
  File "/usr/local/lib/python2.7/dist-packages/django/conf/__init__.py", line 132, in __init__
    mod = importlib.import_module(self.SETTINGS_MODULE)
  File "/usr/local/lib/python2.7/dist-packages/django/utils/importlib.py", line 35, in import_module
    __import__(name)
  File "./bartalk/settings.py", line 4, in <module>
    Database.connect()
  File "./tools/database.py", line 61, in connect
    Database.connection = Database.engine.connect()
  File "/usr/local/lib/python2.7/dist-packages/sqlalchemy/engine/base.py", line 1641, in connect
    return self._connection_cls(self, **kwargs)
  File "/usr/local/lib/python2.7/dist-packages/sqlalchemy/engine/base.py", line 59, in __init__
    self.__connection = connection or engine.raw_connection()
  File "/usr/local/lib/python2.7/dist-packages/sqlalchemy/engine/base.py", line 1699, in raw_connection
    return self.pool.unique_connection()
  File "/usr/local/lib/python2.7/dist-packages/sqlalchemy/pool.py", line 220, in unique_connection
    return _ConnectionFairy(self).checkout()
  File "/usr/local/lib/python2.7/dist-packages/sqlalchemy/pool.py", line 431, in __init__
    rec = self._connection_record = pool._do_get()
  File "/usr/local/lib/python2.7/dist-packages/sqlalchemy/pool.py", line 788, in _do_get
    con = self._create_connection()
  File "/usr/local/lib/python2.7/dist-packages/sqlalchemy/pool.py", line 225, in _create_connection
    return _ConnectionRecord(self)
  File "/usr/local/lib/python2.7/dist-packages/sqlalchemy/pool.py", line 318, in __init__
    self.connection = self.__connect()
  File "/usr/local/lib/python2.7/dist-packages/sqlalchemy/pool.py", line 379, in __connect
    connection = self.__pool._creator()
  File "/usr/local/lib/python2.7/dist-packages/sqlalchemy/engine/strategies.py", line 80, in connect
    return dialect.connect(*cargs, **cparams)
  File "/usr/local/lib/python2.7/dist-packages/sqlalchemy/engine/default.py", line 283, in connect
    return self.dbapi.connect(*cargs, **cparams)
  File "/usr/local/lib/python2.7/dist-packages/psycopg2/__init__.py", line 164, in connect
    conn = _connect(dsn, connection_factory=connection_factory, async=async)
sqlalchemy.exc.OperationalError: (OperationalError) fe_sendauth: no password supplied
 None None
[pid: 22170|app: 0|req: 7/7] 153.104.158.128 () {38 vars in 676 bytes} [Wed Nov  6 11:53:02 2013] GET /api/login => generated 0 bytes in 17 msecs (HTTP/1.1 500) 0 headers in 0 bytes (0 switches on core 0)
[uwsgi-python-reloader] module/file ./tools/database.py has been modified
...gracefully killing workers...
Gracefully killing worker 1 (pid: 22170)...
worker 1 buried after 1 seconds
binary reloading uWSGI...
chdir() to /root/bartalk-server
closing all non-uwsgi socket fds > 2 (max_fd = 1024)...
found fd 3 mapped to socket 0 (:9003)
running /usr/local/bin/uwsgi
*** Starting uWSGI 1.9.18.2 (64bit) on [Wed Nov  6 11:54:31 2013] ***
compiled with version: 4.6.3 on 30 October 2013 14:32:07
os: Linux-3.8.0-29-generic #42~precise1-Ubuntu SMP Wed Aug 14 16:19:23 UTC 2013
nodename: emhagman
machine: x86_64
clock source: unix
detected number of CPU cores: 1
current working directory: /root/bartalk-server
detected binary path: /usr/local/bin/uwsgi
!!! no internal routing support, rebuild with pcre support !!!
uWSGI running as root, you can use --uid/--gid/--chroot options
*** WARNING: you are running uWSGI as root !!! (use the --uid flag) *** 
your processes number limit is 3781
your memory page size is 4096 bytes
detected max file descriptor number: 1024
lock engine: pthread robust mutexes
thunder lock: disabled (you can enable it with --thunder-lock)
uwsgi socket 0 inherited INET address :9003 fd 3
Python version: 2.7.3 (default, Sep 26 2013, 20:13:52)  [GCC 4.6.3]
Python main interpreter initialized at 0xcd7040
python threads support enabled
your server socket listen backlog is limited to 100 connections
your mercy for graceful operations on workers is 60 seconds
mapped 145600 bytes (142 KB) for 1 cores
*** Operational MODE: single process ***
WSGI app 0 (mountpoint='') ready in 0 seconds on interpreter 0xcd7040 pid: 22169 (default app)
*** uWSGI is running in multiple interpreter mode ***
gracefully (RE)spawned uWSGI master process (pid: 22169)
spawned uWSGI worker 1 (pid: 22553, cores: 1)
Python auto-reloader enabled
[pid: 22553|app: 0|req: 1/1] 153.104.158.128 () {40 vars in 707 bytes} [Wed Nov  6 12:00:02 2013] GET /api/login => generated 2220 bytes in 255 msecs (HTTP/1.1 404) 1 headers in 51 bytes (1 switches on core 0)
Internal Server Error: /api/bars/list
Traceback (most recent call last):
  File "/usr/local/lib/python2.7/dist-packages/django/core/handlers/base.py", line 92, in get_response
    response = middleware_method(request)
  File "/usr/local/lib/python2.7/dist-packages/django/middleware/common.py", line 69, in process_request
    if (not urlresolvers.is_valid_path(request.path_info, urlconf) and
  File "/usr/local/lib/python2.7/dist-packages/django/core/urlresolvers.py", line 551, in is_valid_path
    resolve(path, urlconf)
  File "/usr/local/lib/python2.7/dist-packages/django/core/urlresolvers.py", line 440, in resolve
    return get_resolver(urlconf).resolve(path)
  File "/usr/local/lib/python2.7/dist-packages/django/core/urlresolvers.py", line 321, in resolve
    sub_match = pattern.resolve(new_path)
  File "/usr/local/lib/python2.7/dist-packages/django/core/urlresolvers.py", line 223, in resolve
    return ResolverMatch(self.callback, args, kwargs, self.name)
  File "/usr/local/lib/python2.7/dist-packages/django/core/urlresolvers.py", line 230, in callback
    self._callback = get_callable(self._callback_str)
  File "/usr/local/lib/python2.7/dist-packages/django/utils/functional.py", line 31, in wrapper
    result = func(*args)
  File "/usr/local/lib/python2.7/dist-packages/django/core/urlresolvers.py", line 97, in get_callable
    mod = import_module(mod_name)
  File "/usr/local/lib/python2.7/dist-packages/django/utils/importlib.py", line 35, in import_module
    __import__(name)
  File "./bar/views.py", line 6, in <module>
    from dateutil.parser import *
ImportError: No module named dateutil.parser
[pid: 22553|app: 0|req: 2/2] 153.104.158.128 () {38 vars in 684 bytes} [Wed Nov  6 12:00:09 2013] GET /api/bars/list => generated 85602 bytes in 131 msecs (HTTP/1.1 500) 1 headers in 63 bytes (1 switches on core 0)
[pid: 22553|app: 0|req: 3/3] 153.104.158.128 () {40 vars in 715 bytes} [Wed Nov  6 12:00:27 2013] GET /api/bars/list => generated 103 bytes in 19 msecs (HTTP/1.1 200) 1 headers in 51 bytes (1 switches on core 0)
